<?xml version="1.0" encoding="utf-8"?>
<robot name="chassis">
  <link name="base_link">
    <inertial>
      <origin xyz="-0.228303970028683 -0.000876202158095252 0.0299134679923336" rpy="0 0 0" />
      <mass value="5.53904527133728" />
      <inertia ixx="0.028475" ixy="0" ixz="0" iyy="0.016389" iyz="0" izz="0.041786" />
    </inertial>
    <visual>
      <origin xyz="0 0 0" rpy="0 0 0" />
      <geometry>
        <mesh filename="package://chassis/meshes/base_link.STL" />
      </geometry>
      <material name="">
        <color rgba="0.847058823529412 0.847058823529412 0.847058823529412 1" />
      </material>
    </visual>
    <collision>
      <origin xyz="0 0 0" rpy="0 0 0" />
      <geometry>
        <mesh filename="package://chassis/meshes/base_link.STL" />
      </geometry>
    </collision>
  </link>

  <link name="hover_center_link">
    <inertial><mass value="0.001" /><inertia ixx="0.00001" ixy="0" ixz="0" iyy="0.00001" iyz="0" izz="0.00001" /></inertial>
  </link>

  <joint name="hover_center_joint" type="fixed">
    <origin xyz="-0.195 0 0.05" rpy="0 0 0" />
    <parent link="base_link" />
    <child link="hover_center_link" />
  </joint>

  <link name="hover_front_link">
    <inertial><mass value="0.01" /><inertia ixx="0.0001" ixy="0" ixz="0" iyy="0.0001" iyz="0" izz="0.0001" /></inertial>
    <visual><geometry><sphere radius="0.03"/></geometry><material name=""><color rgba="0 1 0 1" /></material></visual>
  </link>
  <joint name="hover_front_joint" type="revolute">
    <origin xyz="0.3 0 0" rpy="0 0 0" /> <parent link="hover_center_link" />
    <child link="hover_front_link" />
    <axis xyz="0 0 1" /><limit lower="0" upper="0" effort="0" velocity="0" />
  </joint>

  <link name="hover_back_link">
    <inertial><mass value="0.01" /><inertia ixx="0.0001" ixy="0" ixz="0" iyy="0.0001" iyz="0" izz="0.0001" /></inertial>
    <visual><geometry><sphere radius="0.03"/></geometry><material name=""><color rgba="0 1 0 1" /></material></visual>
  </link>
  <joint name="hover_back_joint" type="revolute">
    <origin xyz="-0.3 0 0" rpy="0 0 0" /> <parent link="hover_center_link" />
    <child link="hover_back_link" />
    <axis xyz="0 0 1" /><limit lower="0" upper="0" effort="0" velocity="0" />
  </joint>

  <link name="hover_left_link">
    <inertial><mass value="0.01" /><inertia ixx="0.0001" ixy="0" ixz="0" iyy="0.0001" iyz="0" izz="0.0001" /></inertial>
    <visual><geometry><sphere radius="0.03"/></geometry><material name=""><color rgba="0 1 0 1" /></material></visual>
  </link>
  <joint name="hover_left_joint" type="revolute">
    <origin xyz="0 0.25 0" rpy="0 0 0" /> <parent link="hover_center_link" />
    <child link="hover_left_link" />
    <axis xyz="0 0 1" /><limit lower="0" upper="0" effort="0" velocity="0" />
  </joint>

  <link name="hover_right_link">
    <inertial><mass value="0.01" /><inertia ixx="0.0001" ixy="0" ixz="0" iyy="0.0001" iyz="0" izz="0.0001" /></inertial>
    <visual><geometry><sphere radius="0.03"/></geometry><material name=""><color rgba="0 1 0 1" /></material></visual>
  </link>
  <joint name="hover_right_joint" type="revolute">
    <origin xyz="0 -0.25 0" rpy="0 0 0" /> <parent link="hover_center_link" />
    <child link="hover_right_link" />
    <axis xyz="0 0 1" /><limit lower="0" upper="0" effort="0" velocity="0" />
  </joint>
  <link name="right_haunch_pitch_link">
    <inertial>
      <origin xyz="0.0339366201033879 -0.0288772647031759 -0.0391803434295923" rpy="0 0 0" />
      <mass value="0.260740535642986" />
      <inertia ixx="0.001" ixy="0" ixz="0" iyy="0.001" iyz="0" izz="0.001" />
    </inertial>
    <visual>
      <origin xyz="0 0 0" rpy="0 0 0" />
      <geometry><mesh filename="package://chassis/meshes/right_haunch_pitch_link.STL" /></geometry>
      <material name=""><color rgba="0.866666666666667 0.909803921568627 1 1" /></material>
    </visual>
    <collision>
      <origin xyz="0 0 0" rpy="0 0 0" />
      <geometry><mesh filename="package://chassis/meshes/right_haunch_pitch_link.STL" /></geometry>
    </collision>
  </link>

  <joint name="right_haunch_pitch_joint" type="revolute">
    <origin xyz="7.89664045233174E-05 -0.189999999999998 0.0155946272161924" rpy="0 0.0280639905110907 0" />
    <parent link="base_link" />
    <child link="right_haunch_pitch_link" />
    <axis xyz="0 1 0" />
    <limit lower="-3.14" upper="3.14" effort="20" velocity="190" />
  </joint>

  <link name="right_heel_wheel_pitch_link">
    <inertial>
      <origin xyz="2.83327654020393E-05 0.0108463559409561 -0.00047526453468056" rpy="0 0 0" />
      <mass value="0.16431979758067" />
      <inertia ixx="0.001" ixy="0" ixz="0" iyy="0.001" iyz="0" izz="0.001" />
    </inertial>
    <visual>
      <origin xyz="0 0 0" rpy="0 0 0" />
      <geometry><mesh filename="package://chassis/meshes/right_heel_wheel_pitch_link.STL" /></geometry>
      <material name=""><color rgba="1 0.168627450980392 0.168627450980392 1" /></material>
    </visual>
    <collision>
      <origin xyz="0 0 0" rpy="0 0 0" />
      <geometry><mesh filename="package://chassis/meshes/right_heel_wheel_pitch_link.STL" /></geometry>
    </collision>
  </link>

  <joint name="right_heel_wheel_pitch_joint" type="revolute">
    <origin xyz="-0.174321789601735 -0.0304999999998289 -0.0397965699009306" rpy="-3.14159265358979 0 0" />
    <parent link="right_haunch_pitch_link" />
    <child link="right_heel_wheel_pitch_link" />
    <axis xyz="0 1 0" />
    <limit lower="-3.14" upper="3.14" effort="3" velocity="469" />
  </joint>

  <link name="right_f_ankle_yaw_link">
    <inertial>
      <origin xyz="7.57543468865585E-06 -0.00339904167627957 -0.0672623930299538" rpy="0 0 0" />
      <mass value="0.156153092702158" />
      <inertia ixx="0.001" ixy="0" ixz="0" iyy="0.001" iyz="0" izz="0.001" />
    </inertial>
    <visual>
      <origin xyz="0 0 0" rpy="0 0 0" />
      <geometry><mesh filename="package://chassis/meshes/right_f_ankle_yaw_link.STL" /></geometry>
      <material name=""><color rgba="1 0.168627450980392 0.168627450980392 1" /></material>
    </visual>
    <collision>
      <origin xyz="0 0 0" rpy="0 0 0" />
      <geometry><mesh filename="package://chassis/meshes/right_f_ankle_yaw_link.STL" /></geometry>
    </collision>
  </link>

  <joint name="right_f_ankle_yaw_joint" type="revolute">
    <origin xyz="0.0861128261146984 -0.0395000000367831 -0.0634768419001519" rpy="0 0.468635050641022 0" />
    <parent link="right_haunch_pitch_link" />
    <child link="right_f_ankle_yaw_link" />
    <axis xyz="0 0 1" />
    <limit lower="-3.14" upper="3.14" effort="7" velocity="200" />
  </joint>

  <link name="right_f_wheel_pitch_link">
    <inertial>
      <origin xyz="0.00018645857181232 -0.0105653113754948 -0.000469045139969045" rpy="0 0 0" />
      <mass value="0.148575729795387" />
      <inertia ixx="0.001" ixy="0" ixz="0" iyy="0.001" iyz="0" izz="0.001" />
    </inertial>
    <visual>
      <origin xyz="0 0 0" rpy="0 0 0" />
      <geometry><mesh filename="package://chassis/meshes/right_f_wheel_pitch_link.STL" /></geometry>
      <material name=""><color rgba="0.101960784313725 0.101960784313725 0.101960784313725 1" /></material>
    </visual>
    <collision>
      <origin xyz="0 0 0" rpy="0 0 0" />
      <geometry><mesh filename="package://chassis/meshes/right_f_wheel_pitch_link.STL" /></geometry>
    </collision>
  </link>

  <joint name="right_f_wheel_pitch_joint" type="revolute">
    <origin xyz="0 -0.0209999999632119 -0.0814999999999685" rpy="-3.14159265358979 -0.468635050641022 0" />
    <parent link="right_f_ankle_yaw_link" />
    <child link="right_f_wheel_pitch_link" />
    <axis xyz="0 1 0" />
    <limit lower="-3.14" upper="3.14" effort="3" velocity="469" />
  </joint>

  <link name="left_haunch_pitch_link">
    <inertial>
      <origin xyz="0.0333993317808816 0.0282019259178099 -0.0381121386887407" rpy="0 0 0" />
      <mass value="0.268684499662383" />
      <inertia ixx="0.001" ixy="0" ixz="0" iyy="0.001" iyz="0" izz="0.001" />
    </inertial>
    <visual>
      <origin xyz="0 0 0" rpy="0 0 0" />
      <geometry><mesh filename="package://chassis/meshes/left_haunch_pitch_link.STL" /></geometry>
      <material name=""><color rgba="0.298039215686275 0.298039215686275 0.298039215686275 1" /></material>
    </visual>
    <collision>
      <origin xyz="0 0 0" rpy="0 0 0" />
      <geometry><mesh filename="package://chassis/meshes/left_haunch_pitch_link.STL" /></geometry>
    </collision>
  </link>

  <joint name="left_haunch_pitch_joint" type="revolute">
    <origin xyz="-7.89664044891225E-05 0.190000000000002 0.0155946272162527" rpy="0 0.0280639905110907 0" />
    <parent link="base_link" />
    <child link="left_haunch_pitch_link" />
    <axis xyz="0 -1 0" />
    <limit lower="-3.14" upper="3.14" effort="20" velocity="190" />
  </joint>

  <link name="left_heel_wheel_pitch_link">
    <inertial>
      <origin xyz="-2.8332765415584E-05 -0.0108463559411216 0.000475264534692037" rpy="0 0 0" />
      <mass value="0.16431979758067" />
      <inertia ixx="0.001" ixy="0" ixz="0" iyy="0.001" iyz="0" izz="0.001" />
    </inertial>
    <visual>
      <origin xyz="0 0 0" rpy="0 0 0" />
      <geometry><mesh filename="package://chassis/meshes/left_heel_wheel_pitch_link.STL" /></geometry>
      <material name=""><color rgba="0.101960784313725 0.101960784313725 0.101960784313725 1" /></material>
    </visual>
    <collision>
      <origin xyz="0 0 0" rpy="0 0 0" />
      <geometry><mesh filename="package://chassis/meshes/left_heel_wheel_pitch_link.STL" /></geometry>
    </collision>
  </link>

  <joint name="left_heel_wheel_pitch_joint" type="revolute">
    <origin xyz="-0.174163918981611 0.030500000000113 -0.0397921382579199" rpy="0 0 3.14159265358979" />
    <parent link="left_haunch_pitch_link" />
    <child link="left_heel_wheel_pitch_link" />
    <axis xyz="0 1 0" />
    <limit lower="-3.14" upper="3.14" effort="3" velocity="469" />
  </joint>

  <link name="left_f_ankle_yaw_link">
    <inertial>
      <origin xyz="3.13864653356255E-06 -0.00321607161635662 -0.0545657739500743" rpy="0 0 0" />
      <mass value="0.0825435398414466" />
      <inertia ixx="0.001" ixy="0" ixz="0" iyy="0.001" iyz="0" izz="0.001" />
    </inertial>
    <visual>
      <origin xyz="0 0 0" rpy="0 0 0" />
      <geometry><mesh filename="package://chassis/meshes/left_f_ankle_yaw_link.STL" /></geometry>
      <material name=""><color rgba="1 0.168627450980392 0.168627450980392 1" /></material>
    </visual>
    <collision>
      <origin xyz="0 0 0" rpy="0 0 0" />
      <geometry><mesh filename="package://chassis/meshes/left_f_ankle_yaw_link.STL" /></geometry>
    </collision>
  </link>

  <joint name="left_f_ankle_yaw_joint" type="revolute">
    <origin xyz="0.0862706968457094 0.0514999999073168 -0.0634724103132592" rpy="0 0.468635050641022 0" />
    <parent link="left_haunch_pitch_link" />
    <child link="left_f_ankle_yaw_link" />
    <axis xyz="0 0 1" />
    <limit lower="-3.14" upper="3.14" effort="7" velocity="200" />
  </joint>

  <link name="left_f_wheel_pitch_link">
    <inertial>
      <origin xyz="-0.000124685208899855 0.0148967342829046 0.000313651395595402" rpy="0 0 0" />
      <mass value="0.222185282656097" />
      <inertia ixx="0.001" ixy="0" ixz="0" iyy="0.001" iyz="0" izz="0.001" />
    </inertial>
    <visual>
      <origin xyz="0 0 0" rpy="0 0 0" />
      <geometry><mesh filename="package://chassis/meshes/left_f_wheel_pitch_link.STL" /></geometry>
      <material name=""><color rgba="0.101960784313725 0.101960784313725 0.101960784313725 1" /></material>
    </visual>
    <collision>
      <origin xyz="0 0 0" rpy="0 0 0" />
      <geometry><mesh filename="package://chassis/meshes/left_f_wheel_pitch_link.STL" /></geometry>
    </collision>
  </link>

  <joint name="left_f_wheel_pitch_joint" type="revolute">
    <origin xyz="0 0.00900000009268098 -0.0814999999999982" rpy="0 0.468635050641022 3.14159265358979" />
    <parent link="left_f_ankle_yaw_link" />
    <child link="left_f_wheel_pitch_link" />
    <axis xyz="0 1 0" />
    <limit lower="-3.14" upper="3.14" effort="3" velocity="469" />
  </joint>

  <link name="left_b_heel_yaw_link">
    <inertial>
      <origin xyz="-1.17994743353833E-06 -0.00394487184425407 -0.0586122801965365" rpy="0 0 0" />
      <mass value="0.071557663530086" />
      <inertia ixx="0.001" ixy="0" ixz="0" iyy="0.001" iyz="0" izz="0.001" />
    </inertial>
    <visual>
      <origin xyz="0 0 0" rpy="0 0 0" />
      <geometry><mesh filename="package://chassis/meshes/left_b_heel_yaw_link.STL" /></geometry>
      <material name=""><color rgba="1 0.168627450980392 0.168627450980392 1" /></material>
    </visual>
    <collision>
      <origin xyz="0 0 0" rpy="0 0 0" />
      <geometry><mesh filename="package://chassis/meshes/left_b_heel_yaw_link.STL" /></geometry>
    </collision>
  </link>

  <joint name="left_b_heel_yaw_joint" type="fixed">
    <origin xyz="-0.385000000085192 0.235500000040191 0" rpy="0 0 0" />
    <parent link="base_link" />
    <child link="left_b_heel_yaw_link" />
    <axis xyz="0 0 0" />
    <limit lower="-3.14" upper="3.14" effort="7" velocity="200" />
  </joint>

  <link name="left_b_wheel_pitch_link">
    <inertial>
      <origin xyz="-0.000410283750143847 -0.0136930162735144 0.000251764755261705" rpy="0 0 0" />
      <mass value="0.15277136109163" />
      <inertia ixx="0.001" ixy="0" ixz="0" iyy="0.001" iyz="0" izz="0.001" />
    </inertial>
    <visual>
      <origin xyz="0 0 0" rpy="0 0 0" />
      <geometry><mesh filename="package://chassis/meshes/left_b_wheel_pitch_link.STL" /></geometry>
      <material name=""><color rgba="0.2 0.2 0.2 1" /></material>
    </visual>
    <collision>
      <origin xyz="0 0 0" rpy="0 0 0" />
      <geometry><mesh filename="package://chassis/meshes/left_b_wheel_pitch_link.STL" /></geometry>
    </collision>
  </link>

  <joint name="left_b_wheel_pitch_joint" type="revolute">
    <origin xyz="4.38394921822294E-05 -0.0140000000403241 -0.0834101217145528" rpy="0 -0.0280639905110915 3.14159265358979" />
    <parent link="left_b_heel_yaw_link" />
    <child link="left_b_wheel_pitch_link" />
    <axis xyz="0 -1 0" />
    <limit lower="-3.14" upper="3.14" effort="3" velocity="469" />
  </joint>

  <link name="right_b_heel_yaw_link">
    <inertial>
      <origin xyz="-1.40904921930307E-05 0.00394487184499281 -0.0586122801965366" rpy="0 0 0" />
      <mass value="0.071557663530086" />
      <inertia ixx="0.001" ixy="0" ixz="0" iyy="0.001" iyz="0" izz="0.001" />
    </inertial>
    <visual>
      <origin xyz="0 0 0" rpy="0 0 0" />
      <geometry><mesh filename="package://chassis/meshes/right_b_heel_yaw_link.STL" /></geometry>
      <material name=""><color rgba="1 0.168627450980392 0.168627450980392 1" /></material>
    </visual>
    <collision>
      <origin xyz="0 0 0" rpy="0 0 0" />
      <geometry><mesh filename="package://chassis/meshes/right_b_heel_yaw_link.STL" /></geometry>
    </collision>
  </link>

  <joint name="right_b_heel_yaw_joint" type="revolute">
    <origin xyz="-0.38499999990586 -0.235500000040753 0" rpy="0 0 0" />
    <parent link="base_link" />
    <child link="right_b_heel_yaw_link" />
    <axis xyz="0 0 1" />
    <limit lower="-3.14" upper="3.14" effort="7" velocity="200" />
  </joint>

  <link name="right_b_wheel_pitch_link">
    <inertial>
      <origin xyz="0.000312581761166664 0.0140363406887482 -0.000177590421288055" rpy="0 0 0" />
      <mass value="0.207199453815074" />
      <inertia ixx="0.001" ixy="0" ixz="0" iyy="0.001" iyz="0" izz="0.001" />
    </inertial>
    <visual>
      <origin xyz="0 0 0" rpy="0 0 0" />
      <geometry><mesh filename="package://chassis/meshes/right_b_wheel_pitch_link.STL" /></geometry>
      <material name=""><color rgba="0.101960784313725 0.101960784313725 0.101960784313725 1" /></material>
    </visual>
    <collision>
      <origin xyz="0 0 0" rpy="0 0 0" />
      <geometry><mesh filename="package://chassis/meshes/right_b_wheel_pitch_link.STL" /></geometry>
    </collision>
  </link>

  <joint name="right_b_wheel_pitch_joint" type="revolute">
    <origin xyz="4.38393128505687E-05 0.0140000000409253 -0.0834101217145524" rpy="3.14159265358979 0.028063990511091 0" />
    <parent link="right_b_heel_yaw_link" />
    <child link="right_b_wheel_pitch_link" />
    <axis xyz="0 -1 0" />
    <limit lower="-3.14" upper="3.14" effort="3" velocity="469" />
  </joint>

  <gazebo reference="base_link"><gravity>false</gravity></gazebo>
  
  <gazebo reference="right_haunch_pitch_link"><gravity>false</gravity></gazebo>
  <gazebo reference="right_heel_wheel_pitch_link"><gravity>false</gravity></gazebo>
  <gazebo reference="right_f_ankle_yaw_link"><gravity>false</gravity></gazebo>
  <gazebo reference="right_f_wheel_pitch_link"><gravity>false</gravity></gazebo>
  <gazebo reference="right_b_heel_yaw_link"><gravity>false</gravity></gazebo>
  <gazebo reference="right_b_wheel_pitch_link"><gravity>false</gravity></gazebo>

  <gazebo reference="left_haunch_pitch_link"><gravity>false</gravity></gazebo>
  <gazebo reference="left_heel_wheel_pitch_link"><gravity>false</gravity></gazebo>
  <gazebo reference="left_f_ankle_yaw_link"><gravity>false</gravity></gazebo>
  <gazebo reference="left_f_wheel_pitch_link"><gravity>false</gravity></gazebo>
  <gazebo reference="left_b_heel_yaw_link"><gravity>false</gravity></gazebo>
  <gazebo reference="left_b_wheel_pitch_link"><gravity>false</gravity></gazebo>

  <gazebo reference="hover_center_link"><gravity>false</gravity></gazebo>
  <gazebo reference="hover_front_link"><gravity>false</gravity></gazebo>
  <gazebo reference="hover_back_link"><gravity>false</gravity></gazebo>
  <gazebo reference="hover_left_link"><gravity>false</gravity></gazebo>
  <gazebo reference="hover_right_link"><gravity>false</gravity></gazebo>

  <gazebo>
    <plugin name="floating_chassis_controller" filename="libgazebo_ros_planar_move.so">
      <ros>
        <namespace>/</namespace>
        <remapping>cmd_vel:=cmd_vel</remapping>
        <remapping>odom:=odom</remapping>
      </ros>
      <update_rate>100.0</update_rate>
      <publish_rate>50.0</publish_rate>
      <publish_odom>true</publish_odom>
      <publish_odom_tf>true</publish_odom_tf>
      <robot_base_frame>base_link</robot_base_frame>
      <odometry_frame>odom</odometry_frame>
      <covariance_x>0.0001</covariance_x>
      <covariance_y>0.0001</covariance_y>
      <covariance_yaw>0.01</covariance_yaw>
    </plugin>
  </gazebo>

  <gazebo>
    <plugin name="force_front" filename="libgazebo_ros_force.so">
      <ros><namespace>/</namespace><remapping>gazebo_ros_force:=force_cmd</remapping></ros>
      <link_name>hover_front_link</link_name>
      <force_frame>world</force_frame>
    </plugin>
  </gazebo>
  <gazebo>
    <plugin name="force_back" filename="libgazebo_ros_force.so">
      <ros><namespace>/</namespace><remapping>gazebo_ros_force:=force_cmd</remapping></ros>
      <link_name>hover_back_link</link_name>
      <force_frame>world</force_frame>
    </plugin>
  </gazebo>
  <gazebo>
    <plugin name="force_left" filename="libgazebo_ros_force.so">
      <ros><namespace>/</namespace><remapping>gazebo_ros_force:=force_cmd</remapping></ros>
      <link_name>hover_left_link</link_name>
      <force_frame>world</force_frame>
    </plugin>
  </gazebo>
  <gazebo>
    <plugin name="force_right" filename="libgazebo_ros_force.so">
      <ros><namespace>/</namespace><remapping>gazebo_ros_force:=force_cmd</remapping></ros>
      <link_name>hover_right_link</link_name>
      <force_frame>world</force_frame>
    </plugin>
  </gazebo>

</robot>